<?xml version="1.0" encoding="utf-8"?>
<!-- This URDF was automatically created by SolidWorks to URDF Exporter! Originally created by Stephen Brawner (brawner@gmail.com) 
     Commit Version: 1.6.0-4-g7f85cfe  Build Version: 1.6.7995.38578
     For more information, please see http://wiki.ros.org/sw_urdf_exporter -->
<robot name="jaka_pro16">
    <!-- LINK -->
    <link name="world" />

    <link name="Link_0">
    <inertial>
      <origin
        xyz="0.00066883 2.1035E-05 0.030319"
        rpy="0 0 0" />
      <mass
        value="2.2971" />
      <inertia
        ixx="0.0078544"
        ixy="-5.8534E-06"
        ixz="1.0075E-05"
        iyy="0.0086528"
        iyz="-3.5104E-07"
        izz="0.015073" />
    </inertial>
    <visual>
      <origin
        xyz="0 0 0"
        rpy="0 0 0" />
      <geometry>
        <mesh
          filename="package://jaka_description/meshes/jaka_pro16_meshes/Link_0.STL" />
      </geometry>
      <material name="">
        <color
          rgba="0.84706 0.84706 0.84706 1" />
      </material>
    </visual>
    <collision>
      <origin
        xyz="0 0 0"
        rpy="0 0 0" />
      <geometry>
        <mesh
          filename="package://jaka_description/meshes/jaka_pro16_meshes/Link_0.STL" />
      </geometry>
    </collision>
  </link>
  <link
    name="Link_1">
    <inertial>
      <origin
        xyz="-8.8598E-07 0.0056159 -0.0066183"
        rpy="0 0 0" />
      <mass
        value="7.5342" />
      <inertia
        ixx="0.055309"
        ixy="8.6463E-08"
        ixz="1.4129E-07"
        iyy="0.053715"
        iyz="-0.00019613"
        izz="0.037383" />
    </inertial>
    <visual>
      <origin
        xyz="0 0 0"
        rpy="0 0 0" />
      <geometry>
        <mesh
          filename="package://jaka_description/meshes/jaka_pro16_meshes/Link_1.STL" />
      </geometry>
      <material
        name="">
        <color
          rgba="0.84706 0.84706 0.84706 1" />
      </material>
    </visual>
    <collision>
      <origin
        xyz="0 0 0"
        rpy="0 0 0" />
      <geometry>
        <mesh
          filename="package://jaka_description/meshes/jaka_pro16_meshes/Link_1.STL" />
      </geometry>
    </collision>
  </link>
 <link
    name="Link_2">
    <inertial>
      <origin
        xyz="0.34322 -1.5035E-07 -0.22974"
        rpy="0 0 0" />
      <mass
        value="22.704" />
      <inertia
        ixx="0.10389"
        ixy="-3.2682E-06"
        ixz="0.010995"
        iyy="2.2488"
        iyz="8.2896E-08"
        izz="2.225" />
    </inertial>
    <visual>
      <origin
        xyz="0 0 0"
        rpy="0 0 0" />
      <geometry>
        <mesh
          filename="package://jaka_description/meshes/jaka_pro16_meshes/Link_2.STL" />
      </geometry>
      <material
        name="">
        <color
          rgba="0.84706 0.84706 0.84706 1" />
      </material>
    </visual>
    <collision>
      <origin
        xyz="0 0 0"
        rpy="0 0 0" />
      <geometry>
        <mesh
          filename="package://jaka_description/meshes/jaka_pro16_meshes/Link_2.STL" />
      </geometry>
    </collision>
  </link>

  <link
    name="Link_3">
    <inertial>
      <origin
        xyz="0.36002 -1.7177E-07 -0.027486"
        rpy="0 0 0" />
      <mass
        value="7.4564" />
      <inertia
        ixx="0.018335"
        ixy="-3.2861E-07"
        ixz="-0.034245"
        iyy="0.53162"
        iyz="4.6068E-08"
        izz="0.52485" />
    </inertial>
    <visual>
      <origin
        xyz="0 0 0"
        rpy="0 0 0" />
      <geometry>
        <mesh
          filename="package://jaka_description/meshes/jaka_pro16_meshes/Link_3.STL" />
      </geometry>
      <material
        name="">
        <color
          rgba="0.84706 0.84706 0.84706 1" />
      </material>
    </visual>
    <collision>
      <origin
        xyz="0 0 0"
        rpy="0 0 0" />
      <geometry>
        <mesh
          filename="package://jaka_description/meshes/jaka_pro16_meshes/Link_3.STL" />
      </geometry>
    </collision>
  </link>
  
  <link
    name="Link_4">
    <inertial>
      <origin
        xyz="-1.0549E-07 -0.001543 0.0033244"
        rpy="0 0 0" />
      <mass
        value="1.9271" />
      <inertia
        ixx="0.0056362"
        ixy="1.9641E-09"
        ixz="2.1723E-08"
        iyy="0.0038863"
        iyz="1.6853E-06"
        izz="0.0054826" />
    </inertial>
    <visual>
      <origin
        xyz="0 0 0"
        rpy="0 0 0" />
      <geometry>
        <mesh
          filename="package://jaka_description/meshes/jaka_pro16_meshes/Link_4.STL" />
      </geometry>
      <material
        name="">
        <color
          rgba="0.84706 0.84706 0.84706 1" />
      </material>
    </visual>
    <collision>
      <origin
        xyz="0 0 0"
        rpy="0 0 0" />
      <geometry>
        <mesh
          filename="package://jaka_description/meshes/jaka_pro16_meshes/Link_4.STL" />
      </geometry>
    </collision>
  </link>
 
  <link
    name="Link_5">
    <inertial>
      <origin
        xyz="-2.1946E-07 -0.00070175 -0.0032303"
        rpy="0 0 0" />
      <mass
        value="1.9835" />
      <inertia
        ixx="0.0060249"
        ixy="-7.5051E-09"
        ixz="-5.2034E-08"
        iyy="0.0039779"
        iyz="1.5982E-05"
        izz="0.0058703" />
    </inertial>
    <visual>
      <origin
        xyz="0 0 0"
        rpy="0 0 0" />
      <geometry>
        <mesh
          filename="package://jaka_description/meshes/jaka_pro16_meshes/Link_5.STL" />
      </geometry>
      <material
        name="">
        <color
          rgba="0.84706 0.84706 0.84706 1" />
      </material>
    </visual>
    <collision>
      <origin
        xyz="0 0 0"
        rpy="0 0 0" />
      <geometry>
        <mesh
          filename="package://jaka_description/meshes/jaka_pro16_meshes/Link_5.STL" />
      </geometry>
    </collision>
  </link>

  <link
    name="Link_6">
    <inertial>
      <origin
        xyz="0.00013752 -0.00019981 -0.026598"
        rpy="0 0 0" />
      <mass
        value="0.42159" />
      <inertia
        ixx="0.00039872"
        ixy="-1.1269E-06"
        ixz="-1.9314E-07"
        iyy="0.00040609"
        iyz="7.9158E-08"
        izz="0.00068642" />
    </inertial>
    <visual>
      <origin
        xyz="0 0 0"
        rpy="0 0 0" />
      <geometry>
        <mesh
          filename="package://jaka_description/meshes/jaka_pro16_meshes/Link_6.STL" />
      </geometry>
      <material
        name="">
        <color
          rgba="0.84706 0.84706 0.84706 1" />
      </material>
    </visual>
    <collision>
      <origin
        xyz="0 0 0"
        rpy="0 0 0" />
      <geometry>
        <mesh
          filename="package://jaka_description/meshes/jaka_pro16_meshes/Link_6.STL" />
      </geometry>
    </collision>
  </link>

<!-- JOINT -->
    <joint name="fixed" type="fixed">
        <parent link="world" />
        <child link="Link_0" />
    </joint>

 <joint
    name="joint_1"
    type="revolute">
    <origin
      xyz="0 0 0.1965"
      rpy="0 0 0" />
    <parent
      link="Link_0" />
    <child
      link="Link_1" />
    <axis
      xyz="0 0 1" />
    <limit
      lower="-6.28"
      upper="6.28"
      effort="10000"
      velocity="2.09" />
  </joint>
  
  <joint
    name="joint_2"
    type="revolute">
    <origin
      xyz="0 0 0"
      rpy="1.5708 0 0" />
    <parent
      link="Link_1" />
    <child
      link="Link_2" />
    <axis
      xyz="0 0 1" />
    <limit
      lower="-1.48"
      upper="4.62"
      effort="12000"
      velocity="2.09" />
  </joint>

<joint
    name="joint_3"
    type="revolute">
    <origin
      xyz="0.819 0 0"
      rpy="0 0 0" />
    <parent
      link="Link_2" />
    <child
      link="Link_3" />
    <axis
      xyz="0 0 1" />
    <limit
      lower="-3.05"
      upper="3.05"
      effort="12000"
      velocity="2.09" />
  </joint>

 <joint
    name="joint_4"
    type="revolute">
    <origin
      xyz="0.687 0 -0.15801"
      rpy="0 0 0" />
    <parent
      link="Link_3" />
    <child
      link="Link_4" />
    <axis
      xyz="0 0 1" />
    <limit
      lower="-1.48"
      upper="4.62"
      effort="8000"
      velocity="3.14" />
  </joint>

  <joint
    name="joint_5"
    type="revolute">
    <origin
      xyz="0 -0.14415 0"
      rpy="1.5708 0 0" />
    <parent
      link="Link_4" />
    <child
      link="Link_5" />
    <axis
      xyz="0 0 1" />
    <limit
      lower="-6.28"
      upper="6.28"
      effort="8000"
      velocity="3.14" />
  </joint>

  <joint
    name="joint_6"
    type="revolute">
    <origin
      xyz="0 0.12665 0"
      rpy="-1.5708 0 0" />
    <parent
      link="Link_5" />
    <child
      link="Link_6" />
    <axis
      xyz="0 0 1" />
    <limit
      lower="-6.28"
      upper="6.28"
      effort="8000"
      velocity="3.14" />
  </joint>

  <transmission name="trans_joint_1">
    <type>transmission_interface/SimpleTransmission</type>
    <joint name="joint_1">
      <hardwareInterface>hardware_interface/PositionJointInterface</hardwareInterface>
    </joint>
    <actuator name="joint_1_motor">
      <hardwareInterface>hardware_interface/PositionJointInterface</hardwareInterface>
      <mechanicalReduction>1</mechanicalReduction>
    </actuator>
  </transmission>
  <transmission name="trans_joint_2">
    <type>transmission_interface/SimpleTransmission</type>
    <joint name="joint_2">
      <hardwareInterface>hardware_interface/PositionJointInterface</hardwareInterface>
    </joint>
    <actuator name="joint_2_motor">
      <hardwareInterface>hardware_interface/PositionJointInterface</hardwareInterface>
      <mechanicalReduction>1</mechanicalReduction>
    </actuator>
  </transmission>
  <transmission name="trans_joint_3">
    <type>transmission_interface/SimpleTransmission</type>
    <joint name="joint_3">
      <hardwareInterface>hardware_interface/PositionJointInterface</hardwareInterface>
    </joint>
    <actuator name="joint_3_motor">
      <hardwareInterface>hardware_interface/PositionJointInterface</hardwareInterface>
      <mechanicalReduction>1</mechanicalReduction>
    </actuator>
  </transmission>
  <transmission name="trans_joint_4">
    <type>transmission_interface/SimpleTransmission</type>
    <joint name="joint_4">
      <hardwareInterface>hardware_interface/PositionJointInterface</hardwareInterface>
    </joint>
    <actuator name="joint_4_motor">
      <hardwareInterface>hardware_interface/PositionJointInterface</hardwareInterface>
      <mechanicalReduction>1</mechanicalReduction>
    </actuator>
  </transmission>
  <transmission name="trans_joint_5">
    <type>transmission_interface/SimpleTransmission</type>
    <joint name="joint_5">
      <hardwareInterface>hardware_interface/PositionJointInterface</hardwareInterface>
    </joint>
    <actuator name="joint_5_motor">
      <hardwareInterface>hardware_interface/PositionJointInterface</hardwareInterface>
      <mechanicalReduction>1</mechanicalReduction>
    </actuator>
  </transmission>
  <transmission name="trans_joint_6">
    <type>transmission_interface/SimpleTransmission</type>
    <joint name="joint_6">
      <hardwareInterface>hardware_interface/PositionJointInterface</hardwareInterface>
    </joint>
    <actuator name="joint_6_motor">
      <hardwareInterface>hardware_interface/PositionJointInterface</hardwareInterface>
      <mechanicalReduction>1</mechanicalReduction>
    </actuator>
  </transmission>
  <gazebo>
    <plugin name="gazebo_ros_control" filename="libgazebo_ros_control.so">
      <robotNamespace>/</robotNamespace>
    </plugin>
  </gazebo>

</robot>
