<?xml version="1.0" encoding="utf-8"?>
<!-- This URDF was automatically created by SolidWorks to URDF Exporter! Originally created by Stephen Brawner (brawner@gmail.com) 
     Commit Version: 1.5.1-0-g916b5db  Build Version: 1.5.7152.31018
     For more information, please see http://wiki.ros.org/sw_urdf_exporter -->
<robot
  name="jaka_zu18">

  <link name="world" />
  

  <joint name="fixed" type="fixed">
    <origin xyz="0 0 0" rpy="0 0 0" />
     <parent link="world"/>
     <child link="Link_0"/>
  </joint>

  <link
    name="Link_0">
    <inertial>
      <origin
        xyz="0.00090083 -2.9488E-07 0.020561"
        rpy="0 0 0" />
      <mass
        value="0.8175" />
      <inertia
        ixx="0.010034"
        ixy="-3.1423E-09"
        ixz="5.025E-05"
        iyy="0.01287"
        iyz="2.3128E-08"
        izz="0.021463" />
    </inertial>
    <visual>
      <origin
        xyz="0 0 0"
        rpy="0 0 0" />
      <geometry>
        <mesh
          filename="package://jaka_description/meshes/jaka_zu18_meshes/base_link.STL" />
      </geometry>
      <material
        name="">
        <color
          rgba="0.64706 0.61961 0.58824 1" />
      </material>
    </visual>
    <collision>
      <origin
        xyz="0 0 0"
        rpy="0 0 0" />
      <geometry>
        <mesh
          filename="package://jaka_description/meshes/jaka_zu18_meshes/base_link.STL" />
      </geometry>
    </collision>
  </link>
  <link
    name="Link_1">
    <inertial>
      <origin
        xyz="-1.3532E-07 0.0039698 -0.0033275"
        rpy="0 0 0" />
      <mass
        value="3.78" />
      <inertia
        ixx="0.13784"
        ixy="1.785E-07"
        ixz="-5.8341E-07"
        iyy="0.1346"
        iyz="-0.00028533"
        izz="0.092584" />
    </inertial>
    <visual>
      <origin
        xyz="0 0 0"
        rpy="0 0 0" />
      <geometry>
        <mesh
          filename="package://jaka_description/meshes/jaka_zu18_meshes/Link_01.STL" />
      </geometry>
      <material
        name="">
        <color
          rgba="0.64706 0.61961 0.58824 1" />
      </material>
    </visual>
    <collision>
      <origin
        xyz="0 0 0"
        rpy="0 0 0" />
      <geometry>
        <mesh
          filename="package://jaka_description/meshes/jaka_zu18_meshes/Link_01.STL" />
      </geometry>
    </collision>
  </link>
  <joint
    name="joint_1"
    type="revolute">
    <origin
      xyz="0 0 0.14265"
      rpy="0 0 0" />
    <parent
      link="Link_0" />
    <child
      link="Link_1" />
    <axis
      xyz="0 0 1" />
    <limit
      lower="-6.28"
      upper="6.28"
      effort="2000"
      velocity="2.09" />
    <dynamics damping="30" friction="20"/>
  </joint>
  <link
    name="Link_2">
    <inertial>
      <origin
        xyz="0.20686 3.446E-07 -0.18004"
        rpy="0 0 0" />
      <mass
        value="9.68" />
      <inertia
        ixx="0.2333"
        ixy="1.612E-06"
        ixz="0.013448"
        iyy="3.2427"
        iyz="1.1055E-07"
        izz="3.1836" />
    </inertial>
    <visual>
      <origin
        xyz="0 0 0"
        rpy="0 0 0" />
      <geometry>
        <mesh
          filename="package://jaka_description/meshes/jaka_zu18_meshes/Link_02.STL" />
      </geometry>
      <material
        name="">
        <color
          rgba="0.64706 0.61961 0.58824 1" />
      </material>
    </visual>
    <collision>
      <origin
        xyz="0 0 0"
        rpy="0 0 0" />
      <geometry>
        <mesh
          filename="package://jaka_description/meshes/jaka_zu18_meshes/Link_02.STL" />
      </geometry>
    </collision>
  </link>
  <joint
    name="joint_2"
    type="revolute">
    <origin
      xyz="0 0 0"
      rpy="1.5708 0 0" />
    <parent
      link="Link_1" />
    <child
      link="Link_2" />
    <axis
      xyz="0 0 1" />
    <limit
      lower="-1.48"
      upper="4.62"
      effort="8000"
      velocity="2.09" />
    <dynamics damping="30" friction="20"/>
  </joint>
  <link
    name="Link_3">
    <inertial>
      <origin
        xyz="0.2114 -1.2507E-07 -0.046052"
        rpy="0 0 0" />
      <mass
        value="3.1" />
      <inertia
        ixx="0.030746"
        ixy="2.2248E-07"
        ixz="-0.026496"
        iyy="0.59871"
        iyz="-7.3813E-08"
        izz="0.59285" />
    </inertial>
    <visual>
      <origin
        xyz="0 0 0"
        rpy="0 0 0" />
      <geometry>
        <mesh
          filename="package://jaka_description/meshes/jaka_zu18_meshes/Link_03.STL" />
      </geometry>
      <material
        name="">
        <color
          rgba="0.64706 0.61961 0.58824 1" />
      </material>
    </visual>
    <collision>
      <origin
        xyz="0 0 0"
        rpy="0 0 0" />
      <geometry>
        <mesh
          filename="package://jaka_description/meshes/jaka_zu18_meshes/Link_03.STL" />
      </geometry>
    </collision>
  </link>
  <joint
    name="joint_3"
    type="revolute">
    <origin
      xyz="0.51 0 0"
      rpy="0 0 0" />
    <parent
      link="Link_2" />
    <child
      link="Link_3" />
    <axis
      xyz="0 0 1" />
    <limit
      lower="-3.05"
      upper="3.05"
      effort="8000"
      velocity="3.14" />
    <dynamics damping="13" friction="10"/>
  </joint>
  <link
    name="Link_4">
    <inertial>
      <origin
        xyz="4.6823E-07 -0.003388 0.0032625"
        rpy="0 0 0" />
      <mass
        value="0.88" />
      <inertia
        ixx="0.012275"
        ixy="7.981E-09"
        ixz="-1.3755E-08"
        iyy="0.0082652"
        iyz="-7.0839E-05"
        izz="0.011814" />
    </inertial>
    <visual>
      <origin
        xyz="0 0 0"
        rpy="0 0 0" />
      <geometry>
        <mesh
          filename="package://jaka_description/meshes/jaka_zu18_meshes/Link_04.STL" />
      </geometry>
      <material
        name="">
        <color
          rgba="0.64706 0.61961 0.58824 1" />
      </material>
    </visual>
    <collision>
      <origin
        xyz="0 0 0"
        rpy="0 0 0" />
      <geometry>
        <mesh
          filename="package://jaka_description/meshes/jaka_zu18_meshes/Link_04.STL" />
      </geometry>
    </collision>
  </link>
  <joint
    name="joint_4"
    type="revolute">
    <origin
      xyz="0.4 0 -0.154"
      rpy="0 0 0" />
    <parent
      link="Link_3" />
    <child
      link="Link_4" />
    <axis
      xyz="0 0 1" />
    <limit
      lower="-1.48"
      upper="4.62"
      effort="5000"
      velocity="3.14" />
    <dynamics damping="3.5" friction="3"/>
  </joint>
  <link
    name="Link_5">
    <inertial>
      <origin
        xyz="3.9968E-07 0.001346 -0.0031552"
        rpy="0 0 0" />
      <mass
        value="1" />
      <inertia
        ixx="0.013285"
        ixy="-5.0084E-09"
        ixz="2.0733E-08"
        iyy="0.0085081"
        iyz="-2.45E-05"
        izz="0.012821" />
    </inertial>
    <visual>
      <origin
        xyz="0 0 0"
        rpy="0 0 0" />
      <geometry>
        <mesh
          filename="package://jaka_description/meshes/jaka_zu18_meshes/Link_05.STL" />
      </geometry>
      <material
        name="">
        <color
          rgba="0.64706 0.61961 0.58824 1" />
      </material>
    </visual>
    <collision>
      <origin
        xyz="0 0 0"
        rpy="0 0 0" />
      <geometry>
        <mesh
          filename="package://jaka_description/meshes/jaka_zu18_meshes/Link_05.STL" />
      </geometry>
    </collision>
  </link>
  <joint
    name="joint_5"
    type="revolute">
    <origin
      xyz="0 -0.115 0"
      rpy="1.5708 0 0" />
    <parent
      link="Link_4" />
    <child
      link="Link_5" />
    <axis
      xyz="0 0 1" />
    <limit
      lower="-6.28"
      upper="6.28"
      effort="5000"
      velocity="3.14" />
    <dynamics damping="3.5" friction="3"/>
  </joint>
  <link
    name="Link_6">
    <inertial>
      <origin
        xyz="2.2277E-05 0.00011612 -0.021557"
        rpy="0 0 0" />
      <mass
        value="0.22" />
      <inertia
        ixx="0.0010745"
        ixy="-6.8627E-07"
        ixz="-6.4908E-07"
        iyy="0.0010759"
        iyz="1.8508E-06"
        izz="0.0017797" />
    </inertial>
    <visual>
      <origin
        xyz="0 0 0"
        rpy="0 0 0" />
      <geometry>
        <mesh
          filename="package://jaka_description/meshes/jaka_zu18_meshes/Link_06.STL" />
      </geometry>
      <material
        name="">
        <color
          rgba="0.64706 0.61961 0.58824 1" />
      </material>
    </visual>
    <collision>
      <origin
        xyz="0 0 0"
        rpy="0 0 0" />
      <geometry>
        <mesh
          filename="package://jaka_description/meshes/jaka_zu18_meshes/Link_06.STL" />
      </geometry>
    </collision>
  </link>
  <joint
    name="joint_6"
    type="revolute">
    <origin
      xyz="0 0.1035 0"
      rpy="-1.5708 0 0" />
    <parent
      link="Link_5" />
    <child
      link="Link_6" />
    <axis
      xyz="0 0 1" />
    <limit
      lower="-6.28"
      upper="6.28"
      effort="500"
      velocity="3.14" />
    <dynamics damping="3.5" friction="3"/>
  </joint>

  <transmission name="trans_joint_1">
    <type>transmission_interface/SimpleTransmission</type>
    <joint name="joint_1">
      <hardwareInterface>hardware_interface/PositionJointInterface</hardwareInterface>
    </joint>
    <actuator name="joint_1_motor">
      <hardwareInterface>hardware_interface/PositionJointInterface</hardwareInterface>
      <mechanicalReduction>1</mechanicalReduction>
    </actuator>
  </transmission>
  <transmission name="trans_joint_2">
    <type>transmission_interface/SimpleTransmission</type>
    <joint name="joint_2">
      <hardwareInterface>hardware_interface/PositionJointInterface</hardwareInterface>
    </joint>
    <actuator name="joint_2_motor">
      <hardwareInterface>hardware_interface/PositionJointInterface</hardwareInterface>
      <mechanicalReduction>1</mechanicalReduction>
    </actuator>
  </transmission>
  <transmission name="trans_joint_3">
    <type>transmission_interface/SimpleTransmission</type>
    <joint name="joint_3">
      <hardwareInterface>hardware_interface/PositionJointInterface</hardwareInterface>
    </joint>
    <actuator name="joint_3_motor">
      <hardwareInterface>hardware_interface/PositionJointInterface</hardwareInterface>
      <mechanicalReduction>1</mechanicalReduction>
    </actuator>
  </transmission>
  <transmission name="trans_joint_4">
    <type>transmission_interface/SimpleTransmission</type>
    <joint name="joint_4">
      <hardwareInterface>hardware_interface/PositionJointInterface</hardwareInterface>
    </joint>
    <actuator name="joint_4_motor">
      <hardwareInterface>hardware_interface/PositionJointInterface</hardwareInterface>
      <mechanicalReduction>1</mechanicalReduction>
    </actuator>
  </transmission>
  <transmission name="trans_joint_5">
    <type>transmission_interface/SimpleTransmission</type>
    <joint name="joint_5">
      <hardwareInterface>hardware_interface/PositionJointInterface</hardwareInterface>
    </joint>
    <actuator name="joint_5_motor">
      <hardwareInterface>hardware_interface/PositionJointInterface</hardwareInterface>
      <mechanicalReduction>1</mechanicalReduction>
    </actuator>
  </transmission>
  <transmission name="trans_joint_6">
    <type>transmission_interface/SimpleTransmission</type>
    <joint name="joint_6">
      <hardwareInterface>hardware_interface/PositionJointInterface</hardwareInterface>
    </joint>
    <actuator name="joint_6_motor">
      <hardwareInterface>hardware_interface/PositionJointInterface</hardwareInterface>
      <mechanicalReduction>1</mechanicalReduction>
    </actuator>
  </transmission>
  <gazebo>
    <plugin name="gazebo_ros_control" filename="libgazebo_ros_control.so">
      <robotNamespace>/</robotNamespace>
    </plugin>
  </gazebo>
</robot>
