<?xml version="1.0" encoding="utf-8"?>
<!-- This URDF was automatically created by SolidWorks to URDF Exporter! Originally created by Stephen Brawner (brawner@gmail.com) 
     Commit Version: 1.5.0-0-g9aa0fdb  Build Version: 1.5.7004.21443
     For more information, please see http://wiki.ros.org/sw_urdf_exporter -->
<robot name="jaka_zu12">
  <!-- LINK -->
  <link name="world" />

  <link name="Link_0">
    <inertial>
      <origin
        xyz="3.01643284384016E-05 -0.000681463570921656 -0.0225912828938222"
        rpy="0 0 0" />
      <mass
        value="0.8" />
      <inertia
        ixx="0.0102472789321389"
        ixy="-1.25211096927899E-05"
        ixz="-2.032215901439E-07"
        iyy="0.00775885552091728"
        iyz="4.74326539193397E-05"
        izz="0.0171648317580214" />
    </inertial>
    <visual>
      <origin
        xyz="0 0 0"
        rpy="0 0 0" />
      <geometry>
        <mesh
          filename="package://jaka_description/meshes/jaka_zu12_meshes/base_link.STL" />
      </geometry>
      <material
        name="">
        <color
          rgba="1 1 1 1" />
      </material>
    </visual>
    <collision>
      <origin
        xyz="0 0 0"
        rpy="0 0 0" />
      <geometry>
        <mesh
          filename="package://jaka_description/meshes/jaka_zu12_meshes/base_link.STL" />
      </geometry>
    </collision>
  </link>

  <link name="Link_1">
    <inertial>
      <origin
        xyz="-0.000328431560018958 0.00406089906856803 -0.0250109305609668"
        rpy="0 0 0" />
      <mass
        value="3.78" />
      <inertia
        ixx="0.0404051529004393"
        ixy="-5.35916937084468E-05"
        ixz="8.56853276426298E-05"
        iyy="0.0404457306741405"
        iyz="-0.00039414179882763"
        izz="0.0343161527751278" />
    </inertial>
    <visual>
      <origin
        xyz="0 0 0"
        rpy="0 0 0" />
      <geometry>
        <mesh
          filename="package://jaka_description/meshes/jaka_zu12_meshes/1.STL" />
      </geometry>
      <material
        name="">
        <color
          rgba="1 1 1 1" />
      </material>
    </visual>
    <collision>
      <origin
        xyz="0 0 0"
        rpy="0 0 0" />
      <geometry>
        <mesh
          filename="package://jaka_description/meshes/jaka_zu12_meshes/1.STL" />
      </geometry>
    </collision>
  </link>

  <link name="Link_2">
    <inertial>
      <origin
        xyz="0.297499939118518 -1.25165127429216E-08 -0.166069989366573"
        rpy="0 0 0" />
      <mass
        value="12.44" />
      <inertia
        ixx="0.116456439495809"
        ixy="-0.00156765863153774"
        ixz="-3.42571922960543E-06"
        iyy="1.66880550591637"
        iyz="-1.42545474100985E-05"
        izz="1.65302926902866" />
    </inertial>
    <visual>
      <origin
        xyz="0 0 0"
        rpy="0 0 0" />
      <geometry>
        <mesh
          filename="package://jaka_description/meshes/jaka_zu12_meshes/2.STL" />
      </geometry>
      <material
        name="">
        <color
          rgba="1 1 1 1" />
      </material>
    </visual>
    <collision>
      <origin
        xyz="0 0 0"
        rpy="0 0 0" />
      <geometry>
        <mesh
          filename="package://jaka_description/meshes/jaka_zu12_meshes/2.STL" />
      </geometry>
    </collision>
  </link>

  <link name="Link_3">
    <inertial>
      <origin
        xyz="0.294233782543355 -4.72319252706188E-06 -0.0241861096678911"
        rpy="0 0 0" />
      <mass
        value="5.06" />
      <inertia
        ixx="0.0212898342592158"
        ixy="-1.15196860083347E-05"
        ixz="-0.00344346825692792"
        iyy="0.497633875998665"
        iyz="-6.35439617896331E-07"
        izz="0.498513225896089" />
    </inertial>
    <visual>
      <origin
        xyz="0 0 0"
        rpy="0 0 0" />
      <geometry>
        <mesh
          filename="package://jaka_description/meshes/jaka_zu12_meshes/3.STL" />
      </geometry>
      <material
        name="">
        <color
          rgba="1 1 1 1" />
      </material>
    </visual>
    <collision>
      <origin
        xyz="0 0 0"
        rpy="0 0 0" />
      <geometry>
        <mesh
          filename="package://jaka_description/meshes/jaka_zu12_meshes/3.STL" />
      </geometry>
    </collision>
  </link>

  <link name="Link_4">
    <inertial>
      <origin
        xyz="4.22017696188881E-06 -0.0150343523848632 0.00216593552372366"
        rpy="0 0 0" />
      <mass
        value="0.883" />
      <inertia
        ixx="0.00458464465961989"
        ixy="2.63659533420518E-06"
        ixz="-1.52605286509264E-05"
        iyy="0.00363879515047717"
        iyz="-3.19585101806877E-05"
        izz="0.00455871160423887" />
    </inertial>
    <visual>
      <origin
        xyz="0 0 0"
        rpy="0 0 0" />
      <geometry>
        <mesh
          filename="package://jaka_description/meshes/jaka_zu12_meshes/4.STL" />
      </geometry>
      <material
        name="">
        <color
          rgba="1 1 1 1" />
      </material>
    </visual>
    <collision>
      <origin
        xyz="0 0 0"
        rpy="0 0 0" />
      <geometry>
        <mesh
          filename="package://jaka_description/meshes/jaka_zu12_meshes/4.STL" />
      </geometry>
    </collision>
  </link>

  <link name="Link_5">
    <inertial>
      <origin
        xyz="3.86594587120648E-06 0.00426530078104992 -0.00184283112443297"
        rpy="0 0 0" />
      <mass
        value="1" />
      <inertia
        ixx="0.00702353102292446"
        ixy="-2.72522678679305E-06"
        ixz="1.52464540194323E-05"
        iyy="0.00413469714863856"
        iyz="2.81695088352211E-05"
        izz="0.00699581168456812" />
    </inertial>
    <visual>
      <origin
        xyz="0 0 0"
        rpy="0 0 0" />
      <geometry>
        <mesh
          filename="package://jaka_description/meshes/jaka_zu12_meshes/5.STL" />
      </geometry>
      <material
        name="">
        <color
          rgba="1 1 1 1" />
      </material>
    </visual>
    <collision>
      <origin
        xyz="0 0 0"
        rpy="0 0 0" />
      <geometry>
        <mesh
          filename="package://jaka_description/meshes/jaka_zu12_meshes/5.STL" />
      </geometry>
    </collision>
  </link>

  <link name="Link_6">
    <inertial>
      <origin
        xyz="-0.000786084663781494 3.88801034911165E-05 -0.0163246941858815"
        rpy="0 0 0" />
      <mass
        value="0.22" />
      <inertia
        ixx="0.000597975009893646"
        ixy="-2.41634474044304E-05"
        ixz="-6.20059067536115E-06"
        iyy="0.000647976470675928"
        iyz="-6.92746756534325E-07"
        izz="0.00106463342891045" />
    </inertial>
    <visual>
      <origin
        xyz="0 0 0"
        rpy="0 0 0" />
      <geometry>
        <mesh
          filename="package://jaka_description/meshes/jaka_zu12_meshes/6.STL" />
      </geometry>
      <material
        name="">
        <color
          rgba="1 1 1 1" />
      </material>
    </visual>
    <collision>
      <origin
        xyz="0 0 0"
        rpy="0 0 0" />
      <geometry>
        <mesh
          filename="package://jaka_description/meshes/jaka_zu12_meshes/6.STL" />
      </geometry>
    </collision>
  </link>

  <!-- JOINT -->
  <joint name="fixed" type="fixed">
    <origin xyz="0 0 0.04" rpy="0 0 0" />
    <parent link="world"/>
    <child link="Link_0"/>
  </joint>

  <joint name="joint_1" type="continuous">
    <origin xyz="0 0 0.10265" rpy="0 0 0" />
    <parent link="Link_0" />
    <child link="Link_1" />
    <axis xyz="0 0 1" />
    <limit lower="-6.28" upper="6.28" effort="2000" velocity="2.09" />
  </joint>
  
  <joint name="joint_2" type="continuous">
    <origin xyz="0 0 0" rpy="1.5708 0 0" />
    <parent link="Link_1" />
    <child link="Link_2" />
    <axis xyz="0 0 1" />
    <limit lower="-1.48" upper="4.62" effort="8000" velocity="2.09" />  
  </joint>

  <joint name="joint_3" type="continuous">
    <origin xyz="0.595 0 0" rpy="0 0 0" />
    <parent link="Link_2" />
    <child link="Link_3" />
    <axis xyz="0 0 1" />
    <limit lower="-3.05" upper="3.05" effort="8000" velocity="2.09" />
  </joint>

  <joint name="joint_4" type="continuous">
    <origin xyz="0.5715 0 -0.1315" rpy="0 0 0" />
    <parent link="Link_3" />
    <child link="Link_4" />
    <axis xyz="0 0 1" />
    <limit lower="-1.48" upper="4.62" effort="2000" velocity="3.14" />
  </joint>

  <joint name="joint_5" type="continuous">
    <origin xyz="0 -0.115 0" rpy="1.5708 0 0" />
    <parent link="Link_4" />
    <child link="Link_5" />
    <axis xyz="0 0 1" />
    <limit lower="-6.28" upper="6.28" effort="3000" velocity="3.14" />
  </joint>

  <joint name="joint_6" type="continuous">
    <origin xyz="0 0.1035 0" rpy="-1.5708 0 0" />
    <parent link="Link_5" />
    <child link="Link_6" />
    <axis xyz="0 0 1" />
    <limit lower="-6.28" upper="6.28" effort="1000" velocity="3.14" />
  </joint>

  <transmission name="trans_joint_1">
    <type>transmission_interface/SimpleTransmission</type>
    <joint name="joint_1">
      <hardwareInterface>hardware_interface/PositionJointInterface</hardwareInterface>
    </joint>
    <actuator name="joint_1_motor">
      <hardwareInterface>hardware_interface/PositionJointInterface</hardwareInterface>
      <mechanicalReduction>1</mechanicalReduction>
    </actuator>
  </transmission>
  <transmission name="trans_joint_2">
    <type>transmission_interface/SimpleTransmission</type>
    <joint name="joint_2">
      <hardwareInterface>hardware_interface/PositionJointInterface</hardwareInterface>
    </joint>
    <actuator name="joint_2_motor">
      <hardwareInterface>hardware_interface/PositionJointInterface</hardwareInterface>
      <mechanicalReduction>1</mechanicalReduction>
    </actuator>
  </transmission>
  <transmission name="trans_joint_3">
    <type>transmission_interface/SimpleTransmission</type>
    <joint name="joint_3">
      <hardwareInterface>hardware_interface/PositionJointInterface</hardwareInterface>
    </joint>
    <actuator name="joint_3_motor">
      <hardwareInterface>hardware_interface/PositionJointInterface</hardwareInterface>
      <mechanicalReduction>1</mechanicalReduction>
    </actuator>
  </transmission>
  <transmission name="trans_joint_4">
    <type>transmission_interface/SimpleTransmission</type>
    <joint name="joint_4">
      <hardwareInterface>hardware_interface/PositionJointInterface</hardwareInterface>
    </joint>
    <actuator name="joint_4_motor">
      <hardwareInterface>hardware_interface/PositionJointInterface</hardwareInterface>
      <mechanicalReduction>1</mechanicalReduction>
    </actuator>
  </transmission>
  <transmission name="trans_joint_5">
    <type>transmission_interface/SimpleTransmission</type>
    <joint name="joint_5">
      <hardwareInterface>hardware_interface/PositionJointInterface</hardwareInterface>
    </joint>
    <actuator name="joint_5_motor">
      <hardwareInterface>hardware_interface/PositionJointInterface</hardwareInterface>
      <mechanicalReduction>1</mechanicalReduction>
    </actuator>
  </transmission>
  <transmission name="trans_joint_6">
    <type>transmission_interface/SimpleTransmission</type>
    <joint name="joint_6">
      <hardwareInterface>hardware_interface/PositionJointInterface</hardwareInterface>
    </joint>
    <actuator name="joint_6_motor">
      <hardwareInterface>hardware_interface/PositionJointInterface</hardwareInterface>
      <mechanicalReduction>1</mechanicalReduction>
    </actuator>
  </transmission>
  <gazebo>
    <plugin name="gazebo_ros_control" filename="libgazebo_ros_control.so">
      <robotNamespace>/</robotNamespace>
    </plugin>
  </gazebo>
</robot>