<?xml version="1.0" encoding="utf-8"?>
<!-- This URDF was automatically created by SolidWorks to URDF Exporter! Originally created by Stephen Brawner (brawner@gmail.com) 
     Commit Version: 1.6.0-4-g7f85cfe  Build Version: 1.6.7995.38578
     For more information, please see http://wiki.ros.org/sw_urdf_exporter -->
<robot
  name="jaka_s7">

     <!-- LINK -->
  <link name="world" />

  <link
    name="Link_00">
    <inertial>
      <origin
        xyz="0.0028167 -0.00019454 0.019544"
        rpy="0 0 0" />
      <mass
        value="0.52663" />
      <!-- <inertia
        ixx="0.0006297"
        ixy="6.7091E-08"
        ixz="3.4682E-06"
        iyy="0.00095727"
        iyz="2.4476E-07"
        izz="0.0014514" /> -->
        <inertia ixx="0.0048763" ixy="-1.8056E-07" ixz="2.5196E-05" iyy="0.0068003" iyz="-1.7678E-09" izz="0.010618" />
    </inertial>
    
    <visual>
      <origin
        xyz="0 0 0"
        rpy="0 0 0" />
      <geometry>
        <mesh
          filename="package://jaka_description/meshes/jaka_s7_meshes/Link_00.STL" />
      </geometry>
      <material
        name="">
        <color
          rgba="0.84706 0.84706 0.84706 1" />
      </material>
    </visual>
    <collision>
      <origin
        xyz="0 0 0"
        rpy="0 0 0" />
      <geometry>
        <mesh
          filename="package://jaka_description/meshes/jaka_s7_meshes/Link_00.STL" />
      </geometry>
    </collision>
  </link>

  <link
    name="Link_01">
    <inertial>
      <origin
        xyz="-2.5186E-07 0.0033226 -0.001509"
        rpy="0 0 0" />
      <mass
        value="15.135" />
      <inertia ixx="0.044302" ixy="1.5349E-07" ixz="-6.1966E-07" iyy="0.043091" iyz="1.4326E-05" izz="0.030523" />
    </inertial> 
    
    <visual>
      <origin
        xyz="0 0 0"
        rpy="0 0 0" />
      <geometry>
        <mesh
          filename="package://jaka_description/meshes/jaka_s7_meshes/Link_01.STL" />
      </geometry>
      <material
        name="">
        <color
          rgba="0.84706 0.84706 0.84706 1" />
      </material>
    </visual>
    <collision>
      <origin
        xyz="0 0 0"
        rpy="0 0 0" />
      <geometry>
        <mesh
          filename="package://jaka_description/meshes/jaka_s7_meshes/Link_01.STL" />
      </geometry>
    </collision>
  </link>

  <link
    name="Link_02">
    <inertial>
      <origin
        xyz="5.5172E-08 0.18004 -0.14306"
        rpy="0 0 0" />
      <mass
        value="5.459" />
      <!-- <inertia
        ixx="0.14154"
        ixy="1.8956E-07"
        ixz="-1.8902E-08"
        iyy="0.012901"
        iyz="-9.5532E-06"
        izz="0.13805" /> -->
        <inertia ixx="0.1014" ixy="-1.1106E-06" ixz="-1.3363E-07" iyy="1.1119" iyz="2.9045E-08" izz="1.0844" />
    </inertial>
    
    <visual>
      <origin
        xyz="0 0 0"
        rpy="0 0 0" />
      <geometry>
        <mesh
          filename="package://jaka_description/meshes/jaka_s7_meshes/Link_02.STL" />
      </geometry>
      <material
        name="">
        <color
          rgba="0.79216 0.81961 0.93333 1" />
      </material>
    </visual>
    <collision>
      <origin
        xyz="0 0 0"
        rpy="0 0 0" />
      <geometry>
        <mesh
          filename="package://jaka_description/meshes/jaka_s7_meshes/Link_02.STL" />
      </geometry>
    </collision>
  </link>

  <link
    name="Link_03">
    <inertial>
      <origin
        xyz="3.9934E-07 0.15497 -0.012633"
        rpy="0 0 0" />
      <mass
        value="2.1077" />
      <!-- <inertia
        ixx="0.036078"
        ixy="4.7377E-07"
        ixz="1.3969E-08"
        iyy="0.0026619"
        iyz="-0.0023256"
        izz="0.035426" /> -->
      <inertia ixx="0.020968" ixy="-3.9001E-06" ixz="-0.018394" iyy="0.28365" iyz="-1.2859E-07" izz="0.27848" />
    </inertial>
    
    <visual>
      <origin
        xyz="0 0 0"
        rpy="0 0 0" />
      <geometry>
        <mesh
          filename="package://jaka_description/meshes/jaka_s7_meshes/Link_03.STL" />
      </geometry>
      <material
        name="">
        <color
          rgba="0.79216 0.81961 0.93333 1" />
      </material>
    </visual>
    <collision>
      <origin
        xyz="0 0 0"
        rpy="0 0 0" />
      <geometry>
        <mesh
          filename="package://jaka_description/meshes/jaka_s7_meshes/Link_03.STL" />
      </geometry>
    </collision>
  </link>

  <link
    name="Link_04">
    <inertial>
      <origin
        xyz="2.1366E-06 0.0058919 0.0026761"
        rpy="0 0 0" />
      <mass
        value="5.5436" />
      <!-- <inertia
        ixx="0.0092224"
        ixy="1.1405E-07"
        ixz="1.2691E-08"
        iyy="0.0052149"
        iyz="8.4855E-05"
        izz="0.0089344" /> -->
      <inertia ixx="0.0092564" ixy="1.1341E-07" ixz="-1.2578E-08" iyy="0.0052251" iyz="-8.3499E-05" izz="0.0089683" />
    </inertial>
    
    <visual>
      <origin
        xyz="0 0 0"
        rpy="0 0 0" />
      <geometry>
        <mesh
          filename="package://jaka_description/meshes/jaka_s7_meshes/Link_04.STL" />
      </geometry>
      <material
        name="">
        <color
          rgba="0.84706 0.84706 0.84706 1" />
      </material>
    </visual>
    <collision>
      <origin
        xyz="0 0 0"
        rpy="0 0 0" />
      <geometry>
        <mesh
          filename="package://jaka_description/meshes/jaka_s7_meshes/Link_04.STL" />
      </geometry>
    </collision>
  </link>
  
  <link
    name="Link_05">
    <inertial>
      <origin
        xyz="1.6838E-06 0.0024332 -0.0023568"
        rpy="0 0 0" />
      <mass
        value="0.80171" />
      <!-- <inertia
        ixx="0.0016264"
        ixy="3.8656E-09"
        ixz="-2.6908E-09"
        iyy="0.00073912"
        iyz="-4.9488E-06"
        izz="0.0015891" /> -->
      <inertia ixx="0.012993" ixy="-1.0764E-07" ixz="5.8559E-09" iyy="0.0058454" iyz="4.5426E-05" izz="0.0127" />
    </inertial>
    <visual>
      <origin
        xyz="0 0 0"
        rpy="0 0 0" />
      <geometry>
        <mesh
          filename="package://jaka_description/meshes/jaka_s7_meshes/Link_05.STL" />
      </geometry>
      <material
        name="">
        <color
          rgba="0.84706 0.84706 0.84706 1" />
      </material>
    </visual>
    <collision>
      <origin
        xyz="0 0 0"
        rpy="0 0 0" />
      <geometry>
        <mesh
          filename="package://jaka_description/meshes/jaka_s7_meshes/Link_05.STL" />
      </geometry>
    </collision>
  </link>

  <link
    name="Link_06">
    <inertial>
      <origin
        xyz="2.5274E-05 4.9755E-05 -0.025439"
        rpy="0 0 0" />
      <mass
        value="0.22282" />
      <!-- <inertia
        ixx="0.00012606"
        ixy="-6.8589E-08"
        ixz="-5.8199E-08"
        iyy="0.00012662"
        iyz="2.9533E-07"
        izz="0.00017841" /> -->
      <inertia ixx="0.00071853" ixy="-6.9778E-07" ixz="-6.378E-07" iyy="0.00072375" iyz="8.3072E-07" izz="0.0011337" />
    </inertial>
    <visual>
      <origin
        xyz="0 0 0"
        rpy="0 0 0" />
      <geometry>
        <mesh
          filename="package://jaka_description/meshes/jaka_s7_meshes/Link_06.STL" />
      </geometry>
      <material
        name="">
        <color
          rgba="0.79216 0.81961 0.93333 1" />
      </material>
    </visual>
    <collision>
      <origin
        xyz="0 0 0"
        rpy="0 0 0" />
      <geometry>
        <mesh
          filename="package://jaka_description/meshes/jaka_s7_meshes/Link_06.STL" />
      </geometry>
    </collision>
  </link>
  
  <!-- JOINT -->
  <joint name="fixed" type="fixed">
    <origin xyz="0 0.0002282 0" rpy="0 0 0" />
     <parent link="world"/>
     <child link="Link_00"/>
  </joint>

<joint
    name="joint_1"
    type="revolute">
    <origin
      xyz="0 -0.00022535 0.12015"
      rpy="0 0 0" />
    <parent
      link="Link_00" />
    <child
      link="Link_01" />
    <axis
      xyz="0 0 1" />
    <limit
      lower="-6.28"
      upper="6.28"
      effort="2000"
      velocity="3.14" />
  </joint>


  <joint
    name="joint_2"
    type="revolute">
    <origin
      xyz="0 0 0"
      rpy="1.5708 1.5708 0" />
    <parent
      link="Link_01" />
    <child
      link="Link_02" />
    <axis
      xyz="0 0 1" />
    <limit
      lower="-1.48"
      upper="4.62"
      effort="2000"
      velocity="3.14" />
  </joint>

  <joint
    name="joint_3"
    type="revolute">
    <origin
      xyz="0 0.36 0"
      rpy="0 0 0" />
    <parent
      link="Link_02" />
    <child
      link="Link_03" />
    <axis
      xyz="0 0 1" />
    <limit
      lower="-3.05"
      upper="3.05"
      effort="15000"
      velocity="3.14" />
  </joint>

  <joint
    name="joint_4"
    type="revolute">
    <origin
      xyz="0 0.3035 -0.11501"
      rpy="0 0 -1.5708" />
    <parent
      link="Link_03" />
    <child
      link="Link_04" />
    <axis
      xyz="0 0 1" />
    <limit
      lower="-1.48"
      upper="4.62"
      effort="1000"
      velocity="3.14" />
  </joint>

  <joint
    name="joint_5"
    type="revolute">
    <origin
      xyz="0 0.1135 0"
      rpy="-1.5708 0 0" />
    <parent
      link="Link_04" />
    <child
      link="Link_05" />
    <axis
      xyz="0 0 1" />
    <limit
      lower="-6.28"
      upper="6.28"
      effort="5000"
      velocity="3.14" />
  </joint>

  <joint
    name="joint_6"
    type="revolute">
    <origin
      xyz="0 -0.1175 0"
      rpy="1.5708 0 0" />
    <parent
      link="Link_05" />
    <child
      link="Link_06" />
    <axis
      xyz="0 0 1" />
    <limit
      lower="-6.28"
      upper="6.28"
      effort="1000"
      velocity="3.14" />
  </joint>

 <transmission name="trans_joint_1">
        <type>transmission_interface/SimpleTransmission</type>
        <joint name="joint_1">
            <hardwareInterface>hardware_interface/PositionJointInterface</hardwareInterface>
        </joint>
        <actuator name="joint_1_motor">
            <hardwareInterface>hardware_interface/PositionJointInterface</hardwareInterface>
            <mechanicalReduction>1</mechanicalReduction>
        </actuator>
    </transmission>
    <transmission name="trans_joint_2">
        <type>transmission_interface/SimpleTransmission</type>
        <joint name="joint_2">
            <hardwareInterface>hardware_interface/PositionJointInterface</hardwareInterface>
        </joint>
        <actuator name="joint_2_motor">
            <hardwareInterface>hardware_interface/PositionJointInterface</hardwareInterface>
            <mechanicalReduction>1</mechanicalReduction>
        </actuator>
    </transmission>
    <transmission name="trans_joint_3">
        <type>transmission_interface/SimpleTransmission</type>
        <joint name="joint_3">    
            <hardwareInterface>hardware_interface/PositionJointInterface</hardwareInterface>
        </joint>
        <actuator name="joint_3_motor">
            <hardwareInterface>hardware_interface/PositionJointInterface</hardwareInterface>
            <mechanicalReduction>1</mechanicalReduction>
        </actuator>
    </transmission>
    <transmission name="trans_joint_4">
        <type>transmission_interface/SimpleTransmission</type>
        <joint name="joint_4">
            <hardwareInterface>hardware_interface/PositionJointInterface</hardwareInterface>
        </joint>
        <actuator name="joint_4_motor">
            <hardwareInterface>hardware_interface/PositionJointInterface</hardwareInterface>
            <mechanicalReduction>1</mechanicalReduction>
        </actuator>
    </transmission>
    <transmission name="trans_joint_5">
        <type>transmission_interface/SimpleTransmission</type>
        <joint name="joint_5">
            <hardwareInterface>hardware_interface/PositionJointInterface</hardwareInterface>
        </joint>
        <actuator name="joint_5_motor">
            <hardwareInterface>hardware_interface/PositionJointInterface</hardwareInterface>
            <mechanicalReduction>1</mechanicalReduction>
        </actuator>
    </transmission>
    <transmission name="trans_joint_6">
        <type>transmission_interface/SimpleTransmission</type>
        <joint name="joint_6">
            <hardwareInterface>hardware_interface/PositionJointInterface</hardwareInterface>
        </joint>
        <actuator name="joint_6_motor">
            <hardwareInterface>hardware_interface/PositionJointInterface</hardwareInterface>
            <mechanicalReduction>1</mechanicalReduction>
        </actuator>
    </transmission>
    <gazebo>
        <plugin name="gazebo_ros_control" filename="libgazebo_ros_control.so">
            <robotNamespace>/</robotNamespace>
        </plugin>
    </gazebo>
</robot>