<?xml version="1.0" encoding="utf-8"?>
<!-- This URDF was automatically created by SolidWorks to URDF Exporter! Originally created by Stephen Brawner (brawner@gmail.com) 
     Commit Version: 1.6.0-4-g7f85cfe  Build Version: 1.6.7995.38578
     For more information, please see http://wiki.ros.org/sw_urdf_exporter -->
<robot
  name="jaka_a12">
  <link name="world" />
  
  <link
    name="base_link">
    <inertial>
      <origin
        xyz="0.00016274 2.3475E-05 0.017516"
        rpy="0 0 0" />
      <mass
        value="0.84938" />
      <inertia
        ixx="0.0015415"
        ixy="5.5705E-08"
        ixz="-1.6043E-07"
        iyy="0.0018861"
        iyz="2.6186E-07"
        izz="0.0032224" />
    </inertial>
    <visual>
      <origin
        xyz="0 0 0"
        rpy="0 0 0" />
      <geometry>
        <mesh
          filename="package://jaka_description/meshes/jaka_a12_meshes/base_link.STL" />
      </geometry>
      <material
        name="">
        <color
          rgba="0.79216 0.81961 0.93333 1" />
      </material>
    </visual>
    <collision>
      <origin
        xyz="0 0 0"
        rpy="0 0 0" />
      <geometry>
        <mesh
          filename="package://jaka_description/meshes/jaka_a12_meshes/base_link.STL" />
      </geometry>
    </collision>
  </link>
    <!-- JOINT -->
  <joint name="fixed" type="fixed">
       <parent link="world"/>
       <child link="base_link"/>
  </joint>

  <link
    name="J1">
    <inertial>
      <origin
        xyz="6.0416E-08 -0.0029272 -0.004247"
        rpy="0 0 0" />
      <mass
        value="3.7579" />
      <inertia
        ixx="0.01765"
        ixy="-2.5806E-07"
        ixz="-1.3081E-07"
        iyy="0.017355"
        iyz="3.4234E-05"
        izz="0.011502" />
    </inertial>
    <visual>
      <origin
        xyz="0 0 0"
        rpy="0 0 0" />
      <geometry>
        <mesh
          filename="package://jaka_description/meshes/jaka_a12_meshes/J1.STL" />
      </geometry>
      <material
        name="">
        <color
          rgba="0.79216 0.81961 0.93333 1" />
      </material>
    </visual>
    <collision>
      <origin
        xyz="0 0 0"
        rpy="0 0 0" />
      <geometry>
        <mesh
          filename="package://jaka_description/meshes/jaka_a12_meshes/J1.STL" />
      </geometry>
    </collision>
  </link>
  <joint
    name="joint_1"
    type="revolute">
    <origin
      xyz="9.3823E-05 0 0.14265"
      rpy="0 0 0" />
    <parent
      link="base_link" />
    <child
      link="J1" />
    <axis
      xyz="0 0 1" />
    <limit
      lower="-6.28"
      upper="6.28"
      effort="2000"
      velocity="2.62" />
  </joint>
  <link
    name="J2">
    <inertial>
      <origin
        xyz="0.32342 7.7419E-08 0.1801"
        rpy="0 0 0" />
      <mass
        value="13.37" />
      <inertia
        ixx="0.038258"
        ixy="3.482E-08"
        ixz="-0.0030725"
        iyy="1.0882"
        iyz="5.5423E-08"
        izz="1.0803" />
    </inertial>
    <visual>
      <origin
        xyz="0 0 0"
        rpy="0 0 0" />
      <geometry>
        <mesh
          filename="package://jaka_description/meshes/jaka_a12_meshes/J2.STL" />
      </geometry>
      <material
        name="">
        <color
          rgba="0.86667 0.86667 0.8902 1" />
      </material>
    </visual>
    <collision>
      <origin
        xyz="0 0 0"
        rpy="0 0 0" />
      <geometry>
        <mesh
          filename="package://jaka_description/meshes/jaka_a12_meshes/J2.STL" />
      </geometry>
    </collision>
  </link>
  <joint
    name="joint_2"
    type="revolute">
    <origin
      xyz="0 0 0"
      rpy="1.5708 0 0" />
    <parent
      link="J1" />
    <child
      link="J2" />
    <axis
      xyz="0 0 1" />
    <limit
      lower="-6.28"
      upper="6.28"
      effort="8000"
      velocity="2.62" />
  </joint>
  <link
    name="J3">
    <inertial>
      <origin
        xyz="-4.2655E-07 -0.0024273 0.002914"
        rpy="0 0 0" />
      <mass
        value="1.9435" />
      <inertia
        ixx="0.0057394"
        ixy="3.386E-10"
        ixz="7.7883E-08"
        iyy="0.0038913"
        iyz="3.3725E-06"
        izz="0.0056521" />
    </inertial>
    <visual>
      <origin
        xyz="0 0 0"
        rpy="0 0 0" />
      <geometry>
        <mesh
          filename="package://jaka_description/meshes/jaka_a12_meshes/J3.STL" />
      </geometry>
      <material
        name="">
        <color
          rgba="0.86667 0.86667 0.8902 1" />
      </material>
    </visual>
    <collision>
      <origin
        xyz="0 0 0"
        rpy="0 0 0" />
      <geometry>
        <mesh
          filename="package://jaka_description/meshes/jaka_a12_meshes/J3.STL" />
      </geometry>
    </collision>
  </link>
  <joint
    name="joint_3"
    type="revolute">
    <origin
      xyz="0.77 0 0.0375"
      rpy="0 0 1.5708" />
    <parent
      link="J2" />
    <child
      link="J3" />
    <axis
      xyz="0 0 1" />
    <limit
      lower="-6.28"
      upper="6.28"
      effort="8000"
      velocity="3.67" />
  </joint>
  <link
    name="J4">
    <inertial>
      <origin
        xyz="3.1406E-08 -0.00097336 -0.21333"
        rpy="0 0 0" />
      <mass
        value="3.903" />
      <inertia
        ixx="0.10135"
        ixy="4.9565E-08"
        ixz="-9.9161E-09"
        iyy="0.10077"
        iyz="0.00080984"
        izz="0.0051085" />
    </inertial>
    <visual>
      <origin
        xyz="0 0 0"
        rpy="0 0 0" />
      <geometry>
        <mesh
          filename="package://jaka_description/meshes/jaka_a12_meshes/J4.STL" />
      </geometry>
      <material
        name="">
        <color
          rgba="0.79216 0.81961 0.93333 1" />
      </material>
    </visual>
    <collision>
      <origin
        xyz="0 0 0"
        rpy="0 0 0" />
      <geometry>
        <mesh
          filename="package://jaka_description/meshes/jaka_a12_meshes/J4.STL" />
      </geometry>
    </collision>
  </link>
  <joint
    name="joint_4"
    type="revolute">
    <origin
      xyz="0 -0.5515 0"
      rpy="-1.5708 0 -3.1416" />
    <parent
      link="J3" />
    <child
      link="J4" />
    <axis
      xyz="0 0 1" />
    <limit
      lower="-6.28"
      upper="6.28"
      effort="2000"
      velocity="3.67" />
  </joint>
  <link
    name="J5">
    <inertial>
      <origin
        xyz="1.1338E-07 0.0049095 -0.0024985"
        rpy="0 0 0" />
      <mass
        value="1.0253" />
      <inertia
        ixx="0.0022543"
        ixy="1.8791E-09"
        ixz="1.7943E-08"
        iyy="0.0011832"
        iyz="-1.3434E-05"
        izz="0.0022184" />
    </inertial>
    <visual>
      <origin
        xyz="0 0 0"
        rpy="0 0 0" />
      <geometry>
        <mesh
          filename="package://jaka_description/meshes/jaka_a12_meshes/J5.STL" />
      </geometry>
      <material
        name="">
        <color
          rgba="0.86667 0.86667 0.8902 1" />
      </material>
    </visual>
    <collision>
      <origin
        xyz="0 0 0"
        rpy="0 0 0" />
      <geometry>
        <mesh
          filename="package://jaka_description/meshes/jaka_a12_meshes/J5.STL" />
      </geometry>
    </collision>
  </link>
  <joint
    name="joint_5"
    type="revolute">
    <origin
      xyz="0 -0.115 0"
      rpy="-1.5708 -1.5708 3.1416" />
    <parent
      link="J4" />
    <child
      link="J5" />
    <axis
      xyz="0 0 1" />
    <limit
      lower="-6.28"
      upper="6.28"
      effort="3000"
      velocity="3.67" />
  </joint>
  <link
    name="J6">
    <inertial>
      <origin
        xyz="-6.1189E-05 -5.6233E-05 -0.020571"
        rpy="0 0 0" />
      <mass
        value="0.2135" />
      <inertia
        ixx="0.00012541"
        ixy="4.199E-07"
        ixz="-2.6224E-08"
        iyy="0.00012595"
        iyz="-1.6646E-07"
        izz="0.00021163" />
    </inertial>
    <visual>
      <origin
        xyz="0 0 0"
        rpy="0 0 0" />
      <geometry>
        <mesh
          filename="package://jaka_description/meshes/jaka_a12_meshes/J6.STL" />
      </geometry>
      <material
        name="">
        <color
          rgba="0.79216 0.81961 0.93333 1" />
      </material>
    </visual>
    <collision>
      <origin
        xyz="0 0 0"
        rpy="0 0 0" />
      <geometry>
        <mesh
          filename="package://jaka_description/meshes/jaka_a12_meshes/J6.STL" />
      </geometry>
    </collision>
  </link>
  <joint
    name="joint_6"
    type="revolute">
    <origin
      xyz="0 -0.1035 0"
      rpy="1.5708 0 0" />
    <parent
      link="J5" />
    <child
      link="J6" />
    <axis
      xyz="0 0 1" />
    <limit
      lower="-6.28"
      upper="6.28"
      effort="1000"
      velocity="3.67" />
  </joint>

  <transmission name="trans_joint_1">
    <type>transmission_interface/SimpleTransmission</type>
    <joint name="joint_1">
      <hardwareInterface>hardware_interface/PositionJointInterface</hardwareInterface>
    </joint>
    <actuator name="joint_1_motor">
      <hardwareInterface>hardware_interface/PositionJointInterface</hardwareInterface>
      <mechanicalReduction>1</mechanicalReduction>
    </actuator>
  </transmission>
  <transmission name="trans_joint_2">
    <type>transmission_interface/SimpleTransmission</type>
    <joint name="joint_2">
      <hardwareInterface>hardware_interface/PositionJointInterface</hardwareInterface>
    </joint>
    <actuator name="joint_2_motor">
      <hardwareInterface>hardware_interface/PositionJointInterface</hardwareInterface>
      <mechanicalReduction>1</mechanicalReduction>
    </actuator>
  </transmission>
  <transmission name="trans_joint_3">
    <type>transmission_interface/SimpleTransmission</type>
    <joint name="joint_3">
      <hardwareInterface>hardware_interface/PositionJointInterface</hardwareInterface>
    </joint>
    <actuator name="joint_3_motor">
      <hardwareInterface>hardware_interface/PositionJointInterface</hardwareInterface>
      <mechanicalReduction>1</mechanicalReduction>
    </actuator>
  </transmission>
  <transmission name="trans_joint_4">
    <type>transmission_interface/SimpleTransmission</type>
    <joint name="joint_4">
      <hardwareInterface>hardware_interface/PositionJointInterface</hardwareInterface>
    </joint>
    <actuator name="joint_4_motor">
      <hardwareInterface>hardware_interface/PositionJointInterface</hardwareInterface>
      <mechanicalReduction>1</mechanicalReduction>
    </actuator>
  </transmission>
  <transmission name="trans_joint_5">
    <type>transmission_interface/SimpleTransmission</type>
    <joint name="joint_5">
      <hardwareInterface>hardware_interface/PositionJointInterface</hardwareInterface>
    </joint>
    <actuator name="joint_5_motor">
      <hardwareInterface>hardware_interface/PositionJointInterface</hardwareInterface>
      <mechanicalReduction>1</mechanicalReduction>
    </actuator>
  </transmission>
  <transmission name="trans_joint_6">
    <type>transmission_interface/SimpleTransmission</type>
    <joint name="joint_6">
      <hardwareInterface>hardware_interface/PositionJointInterface</hardwareInterface>
    </joint>
    <actuator name="joint_6_motor">
      <hardwareInterface>hardware_interface/PositionJointInterface</hardwareInterface>
      <mechanicalReduction>1</mechanicalReduction>
    </actuator>
  </transmission>
  <gazebo>
    <plugin name="gazebo_ros_control" filename="libgazebo_ros_control.so">
      <robotNamespace>/</robotNamespace>
    </plugin>
  </gazebo>
</robot>
