<?xml version="1.0" encoding="utf-8"?>
<!-- This URDF was automatically created by SolidWorks to URDF Exporter! Originally created by Stephen Brawner (brawner@gmail.com) 
     Commit Version: 1.5.1-0-g916b5db  Build Version: 1.5.7152.31018
     For more information, please see http://wiki.ros.org/sw_urdf_exporter -->
<robot
  name="jaka_zu30">

  <link name="world" />


  <link
    name="Empty_Link0">
    <inertial>
      <origin
        xyz="0.0033778 -0.00022265 0.034191"
        rpy="0 0 0" />
      <mass
        value="4.9068" />
      <inertia
        ixx="0.019204"
        ixy="-2.3227E-07"
        ixz="-0.00011247"
        iyy="0.018856"
        iyz="6.6222E-06"
        izz="0.035003" />
    </inertial>
    <visual>
      <origin
        xyz="0 0 0"
        rpy="0 0 0" />
      <geometry>
        <mesh
          filename="package://jaka_description/meshes/jaka_zu30_meshes/Empty_Link0.STL" />
      </geometry>
      <material
        name="">
        <color
          rgba="0.89804 0.91765 0.92941 1" />
      </material>
    </visual>
    <collision>
      <origin
        xyz="0 0 0"
        rpy="0 0 0" />
      <geometry>
        <mesh
          filename="package://jaka_description/meshes/jaka_zu30_meshes/Empty_Link0.STL" />
      </geometry>
    </collision>
  </link>

  <!-- JOINT -->
  <joint name="fixed" type="fixed">
     <parent link="world"/>
     <child link="Empty_Link0"/>
  </joint>

  <link
    name="Empty_Link1">
    <inertial>
      <origin
        xyz="-8.8598E-07 0.0056159 -0.0066183"
        rpy="0 0 0" />
      <mass
        value="7.5342" />
      <inertia
        ixx="0.055309"
        ixy="8.6465E-08"
        ixz="1.4129E-07"
        iyy="0.053715"
        iyz="-0.00019613"
        izz="0.037383" />
    </inertial>
    <visual>
      <origin
        xyz="0 0 0"
        rpy="0 0 0" />
      <geometry>
        <mesh
          filename="package://jaka_description/meshes/jaka_zu30_meshes/Empty_Link1.STL" />
      </geometry>
      <material
        name="">
        <color
          rgba="1 1 1 1" />
      </material>
    </visual>
    <collision>
      <origin
        xyz="0 0 0"
        rpy="0 0 0" />
      <geometry>
        <mesh
          filename="package://jaka_description/meshes/jaka_zu30_meshes/Empty_Link1.STL" />
      </geometry>
    </collision>
  </link>
  <joint
    name="joint_1"
    type="revolute">
    <origin
      xyz="0.0044104 -0.00027834 0.1965"
      rpy="0 0 0" />
    <parent
      link="Empty_Link0" />
    <child
      link="Empty_Link1" />
    <axis
      xyz="0 0 1" />
    <limit
      lower="-6.28"
      upper="6.28"
      effort="3000"
      velocity="2.09" />
  </joint>
  <link
    name="Empty_Link2">
    <inertial>
      <origin
        xyz="0.27137 -2.2132E-07 -0.22936"
        rpy="0 0 0" />
      <mass
        value="19.903" />
      <inertia
        ixx="0.096293"
        ixy="-2.2596E-06"
        ixz="0.0085057"
        iyy="1.3904"
        iyz="-2.8112E-07"
        izz="1.3666" />
    </inertial>
    <visual>
      <origin
        xyz="0 0 0"
        rpy="0 0 0" />
      <geometry>
        <mesh
          filename="package://jaka_description/meshes/jaka_zu30_meshes/Empty_Link2.STL" />
      </geometry>
      <material
        name="">
        <color
          rgba="0.79216 0.81961 0.93333 1" />
      </material>
    </visual>
    <collision>
      <origin
        xyz="0 0 0"
        rpy="0 0 0" />
      <geometry>
        <mesh
          filename="package://jaka_description/meshes/jaka_zu30_meshes/Empty_Link2.STL" />
      </geometry>
    </collision>
  </link>
  <joint
    name="joint_2"
    type="revolute">
    <origin
      xyz="0 0 0"
      rpy="1.5708 0 0" />
    <parent
      link="Empty_Link1" />
    <child
      link="Empty_Link2" />
    <axis
      xyz="0 0 1" />
    <limit
      lower="-1.48"
      upper="4.62"
      effort="9000"
      velocity="2.09" />
  </joint>
  <link
    name="Empty_Link3">
    <inertial>
      <origin
        xyz="0.25044 -7.5432E-07 -0.05733"
        rpy="0 0 0" />
      <mass
        value="6.782" />
      <inertia
        ixx="0.013304"
        ixy="-1.1062E-06"
        ixz="-0.0088098"
        iyy="0.28438"
        iyz="-2.6665E-07"
        izz="0.28253" />
    </inertial>
    <visual>
      <origin
        xyz="0 0 0"
        rpy="0 0 0" />
      <geometry>
        <mesh
          filename="package://jaka_description/meshes/jaka_zu30_meshes/Empty_Link3.STL" />
      </geometry>
      <material
        name="">
        <color
          rgba="0.79216 0.81961 0.93333 1" />
      </material>
    </visual>
    <collision>
      <origin
        xyz="0 0 0"
        rpy="0 0 0" />
      <geometry>
        <mesh
          filename="package://jaka_description/meshes/jaka_zu30_meshes/Empty_Link3.STL" />
      </geometry>
    </collision>
  </link>
  <joint
    name="joint_3"
    type="revolute">
    <origin
      xyz="0.6625 0 0"
      rpy="0 0 0" />
    <parent
      link="Empty_Link2" />
    <child
      link="Empty_Link3" />
    <axis
      xyz="0 0 1" />
    <limit
      lower="-3.05"
      upper="3.05"
      effort="9000"
      velocity="2.09" />
  </joint>
  <link
    name="Empty_Link4">
    <inertial>
      <origin
        xyz="-4.9353E-08 -0.0057267 0.0052352"
        rpy="0 0 0" />
      <mass
        value="1.2892" />
      <inertia
        ixx="0.0031175"
        ixy="1.6387E-09"
        ixz="-4.7004E-09"
        iyy="0.0019091"
        iyz="-3.865E-05"
        izz="0.0029354" />
    </inertial>
    <visual>
      <origin
        xyz="0 0 0"
        rpy="0 0 0" />
      <geometry>
        <mesh
          filename="package://jaka_description/meshes/jaka_zu30_meshes/Empty_Link4.STL" />
      </geometry>
      <material
        name="">
        <color
          rgba="0.84706 0.84706 0.84706 1" />
      </material>
    </visual>
    <collision>
      <origin
        xyz="0 0 0"
        rpy="0 0 0" />
      <geometry>
        <mesh
          filename="package://jaka_description/meshes/jaka_zu30_meshes/Empty_Link4.STL" />
      </geometry>
    </collision>
  </link>
  <joint
    name="joint_4"
    type="revolute">
    <origin
      xyz="0.549 0 -0.18835"
      rpy="0 0 0" />
    <parent
      link="Empty_Link3" />
    <child
      link="Empty_Link4" />
    <axis
      xyz="0 0 1" />
    <limit
      lower="-1.48"
      upper="4.62"
      effort="6000"
      velocity="3.84" />
  </joint>
  <link
    name="Empty_Link5">
    <inertial>
      <origin
        xyz="-4.0193E-08 0.0035719 -0.0051183"
        rpy="0 0 0" />
      <mass
        value="1.33" />
      <inertia
        ixx="0.003343"
        ixy="-3.6485E-10"
        ixz="4.8841E-09"
        iyy="0.0019534"
        iyz="-2.4314E-05"
        izz="0.0031635" />
    </inertial>
    <visual>
      <origin
        xyz="0 0 0"
        rpy="0 0 0" />
      <geometry>
        <mesh
          filename="package://jaka_description/meshes/jaka_zu30_meshes/Empty_Link5.STL" />
      </geometry>
      <material
        name="">
        <color
          rgba="0.84706 0.84706 0.84706 1" />
      </material>
    </visual>
    <collision>
      <origin
        xyz="0 0 0"
        rpy="0 0 0" />
      <geometry>
        <mesh
          filename="package://jaka_description/meshes/jaka_zu30_meshes/Empty_Link5.STL" />
      </geometry>
    </collision>
  </link>
  <joint
    name="joint_5"
    type="revolute">
    <origin
      xyz="0 -0.1385 0"
      rpy="1.5708 0 0" />
    <parent
      link="Empty_Link4" />
    <child
      link="Empty_Link5" />
    <axis
      xyz="0 0 1" />
    <limit
      lower="-6.28"
      upper="6.28"
      effort="6000"
      velocity="3.84" />
  </joint>
  <link
    name="Empty_Link6">
    <inertial>
      <origin
        xyz="-0.00031973 0.00011874 -0.022089"
        rpy="0 0 0" />
      <mass
        value="0.31241" />
      <inertia
        ixx="0.00024421"
        ixy="7.2248E-08"
        ixz="-3.3291E-07"
        iyy="0.00024881"
        iyz="2.0087E-07"
        izz="0.00040651" />
    </inertial>
    <visual>
      <origin
        xyz="0 0 0"
        rpy="0 0 0" />
      <geometry>
        <mesh
          filename="package://jaka_description/meshes/jaka_zu30_meshes/Empty_Link6.STL" />
      </geometry>
      <material
        name="">
        <color
          rgba="0.84706 0.84706 0.84706 1" />
      </material>
    </visual>
    <collision>
      <origin
        xyz="0 0 0"
        rpy="0 0 0" />
      <geometry>
        <mesh
          filename="package://jaka_description/meshes/jaka_zu30_meshes/Empty_Link6.STL" />
      </geometry>
    </collision>
  </link>
  <joint
    name="joint_6"
    type="revolute">
    <origin
      xyz="0.00039033 0.1205 0"
      rpy="-1.5708 0 0" />
    <parent
      link="Empty_Link5" />
    <child
      link="Empty_Link6" />
    <axis
      xyz="0 0 1" />
    <limit
      lower="-6.28"
      upper="6.28"
      effort="2000"
      velocity="3.84" />
  </joint>

  <transmission name="trans_joint_1">
    <type>transmission_interface/SimpleTransmission</type>
    <joint name="joint_1">
      <hardwareInterface>hardware_interface/PositionJointInterface</hardwareInterface>
    </joint>
    <actuator name="joint_1_motor">
      <hardwareInterface>hardware_interface/PositionJointInterface</hardwareInterface>
      <mechanicalReduction>1</mechanicalReduction>
    </actuator>
  </transmission>
  <transmission name="trans_joint_2">
    <type>transmission_interface/SimpleTransmission</type>
    <joint name="joint_2">
      <hardwareInterface>hardware_interface/PositionJointInterface</hardwareInterface>
    </joint>
    <actuator name="joint_2_motor">
      <hardwareInterface>hardware_interface/PositionJointInterface</hardwareInterface>
      <mechanicalReduction>1</mechanicalReduction>
    </actuator>
  </transmission>
  <transmission name="trans_joint_3">
    <type>transmission_interface/SimpleTransmission</type>
    <joint name="joint_3">
      <hardwareInterface>hardware_interface/PositionJointInterface</hardwareInterface>
    </joint>
    <actuator name="joint_3_motor">
      <hardwareInterface>hardware_interface/PositionJointInterface</hardwareInterface>
      <mechanicalReduction>1</mechanicalReduction>
    </actuator>
  </transmission>
  <transmission name="trans_joint_4">
    <type>transmission_interface/SimpleTransmission</type>
    <joint name="joint_4">
      <hardwareInterface>hardware_interface/PositionJointInterface</hardwareInterface>
    </joint>
    <actuator name="joint_4_motor">
      <hardwareInterface>hardware_interface/PositionJointInterface</hardwareInterface>
      <mechanicalReduction>1</mechanicalReduction>
    </actuator>
  </transmission>
  <transmission name="trans_joint_5">
    <type>transmission_interface/SimpleTransmission</type>
    <joint name="joint_5">
      <hardwareInterface>hardware_interface/PositionJointInterface</hardwareInterface>
    </joint>
    <actuator name="joint_5_motor">
      <hardwareInterface>hardware_interface/PositionJointInterface</hardwareInterface>
      <mechanicalReduction>1</mechanicalReduction>
    </actuator>
  </transmission>
  <transmission name="trans_joint_6">
    <type>transmission_interface/SimpleTransmission</type>
    <joint name="joint_6">
      <hardwareInterface>hardware_interface/PositionJointInterface</hardwareInterface>
    </joint>
    <actuator name="joint_6_motor">
      <hardwareInterface>hardware_interface/PositionJointInterface</hardwareInterface>
      <mechanicalReduction>1</mechanicalReduction>
    </actuator>
  </transmission>
  <gazebo>
    <plugin name="gazebo_ros_control" filename="libgazebo_ros_control.so">
      <robotNamespace>/</robotNamespace>
    </plugin>
  </gazebo>
</robot>
